Workbook

Sheet Resumo da Exportação
B3: Este documento foi exportado do Numbers. Cada tabela foi convertida em uma folha do Excel. Todos os outros objetos em cada folha do Numbers foram colocados em folhas à parte. Esteja ciente de que os cálculos de fórmulas podem ser diferentes no Excel.
B7: Nome da Folha do Numbers | C7: Nome da Tabela do Numbers | D7: Nome da Planilha do Excel
B9: AÇÕES
C10: Visão Geral | D10: AÇÕES - Visão Geral
C11: REFERENCIAL | D11: AÇÕES - REFERENCIAL
C12: Meu Portfólio | D12: AÇÕES - Meu Portfólio
C13: Tabela 3 | D13: AÇÕES - Tabela 3
C14: Comparação de FII | D14: AÇÕES - Comparação de FII
C15: “Todos os Desenhos da Folha” | D15: AÇÕES - Desenhos
B16: ETF BRASIL
C17: Visão Geral | D17: ETF BRASIL - Visão Geral
C18: REFERENCIAL | D18: ETF BRASIL - REFERENCIAL
C19: Meu Portfólio | D19: ETF BRASIL - Meu Portfólio
C20: Tabela 3 | D20: ETF BRASIL - Tabela 3
C21: “Todos os Desenhos da Folha” | D21: ETF BRASIL - Desenhos
B22: ETF USA
C23: Visão Geral | D23: ETF USA - Visão Geral
C24: REFERENCIAL | D24: ETF USA - REFERENCIAL
C25: Meu Portfólio | D25: ETF USA - Meu Portfólio
C26: Tabela 1 | D26: ETF USA - Tabela 1
C27: Tabela 2 | D27: ETF USA - Tabela 2
C28: Tabela 3 | D28: ETF USA - Tabela 3
C29: Comparação de FII | D29: ETF USA - Comparação de FII
C30: “Todos os Desenhos da Folha” | D30: ETF USA - Desenhos
B31: Fundos Imobiliários
C32: Visão Geral | D32: Fundos Imobiliários - Visão Ger
C33: REFERENCIAL | D33: Fundos Imobiliários - REFERENCI
C34: Meu Portfólio | D34: Fundos Imobiliários - Meu Portf
C35: Tabela 1 | D35: Fundos Imobiliários - Tabela 1
C36: Tabela 3 | D36: Fundos Imobiliários - Tabela 3
C37: “Todos os Desenhos da Folha” | D37: Fundos Imobiliários - Desenhos
B38: Reit's
C39: Visão Geral | D39: Reit's - Visão Geral
C40: REFERENCIAL | D40: Reit's - REFERENCIAL
C41: Meu Portfólio | D41: Reit's - Meu Portfólio
C42: Tabela 1 | D42: Reit's - Tabela 1
C43: Tabela 3 | D43: Reit's - Tabela 3
C44: “Todos os Desenhos da Folha” | D44: Reit's - Desenhos
B45: STOCKS
C46: Visão Geral | D46: STOCKS - Visão Geral
...

Sheet AÇÕES - Visão Geral
A1: Valor de Mercado | B1: {='AÇÕES - Meu Portfólio'!K$5} -> 39686
A2: Perda/Ganho | B2: {='AÇÕES - Meu Portfólio'!L5-'AÇÕES - Meu Portfólio'!M5} -> -5766 | C2: {=IF(B2>0,"↑",IF(B2<0,"↓","–"))} -> ↓
A3: % Alteração | B3: {='AÇÕES - Meu Portfólio'!O$5} -> -0.17812823 | C3: {=IF(B3="–","–",IF(B3>0,"↑",IF(B3<0,"↓","–")))} -> ↓

Sheet AÇÕES - REFERENCIAL
A1: REFERENCIAL
B2: CAIU 10% OU MAIS EM RELAÇÃO AO PREÇO PAGO
B3: CAIU 20% OU MAIS EM RELAÇÃO AO PREÇO PAGO
B4: SUBIU 10% OU MAIS EM RELAÇÃO AO PREÇO PAGO
B5: SUBIU 20% OU MAIS EM RELAÇÃO AO PREÇO PAGO

Sheet AÇÕES - Meu Portfólio
A2: Símbolo | B2: Nome | C2: Setor | D2: Preço | E2: Preço Pago | F2: Alteração de Preço | G2: % Alteração | H2: Ações | I2: Preço Pago em Dólares Americanos | J2: Quanto Paguei | K2: Valor de Mercado | L2: Ganho | M2: Ganho Anterior | N2: % Ganho | P2: Data de PG Dividendos 1º SEM | Q2: Dividendo Anual por ação | R2: Expectativa de pagamento de dividendos por período | S2: Dividendo recebido | T2: Magic Number | U2: QTD q falta | V2: Com o Dividendo recebido consigo comprar… | W2: Min 52 semanas | X2: Max 52 semanas
A3: MELI34 | B3: MERCADOLIBREDRN | C3: varejo digital (e-commerce) | D3: 73.49 | E3: 87.41 | F3: {=D3-E3} -> -13.92 | G3: {=(D3-E3)/E3} -> -0.15924951 | H3: 400 | I3: 0.20426506 | J3: 34964 | K3: 29396 | L3: {=_xlfn.IFERROR(K3-J3,"–")} -> -5568 | M3: 0 | N3: {=_xlfn.IFERROR((K3-J3)/J3,"–")} -> -0.15924951 | W3: 66.92 | X3: 123.8
A4: BBSE3 | B4: BBSEGURIDADEON NM | C4: seguros, previdência privada aberta e capitalização | D4: 34.3 | E4: 34.96 | F4: {=D4-E4} -> -0.66 | G4: {=(D4-E4)/E4} -> -0.018878719 | H4: 300 | I4: 0.20426506 | J4: 10488 | K4: 10290 | L4: {=_xlfn.IFERROR(K4-J4,"–")} -> -198 | M4: 0 | N4: {=_xlfn.IFERROR((K4-J4)/J4,"–")} -> -0.018878719 | P4: 46083 | Q4: 5.21 | R4: 2.605 | S4: {=R4*H4} -> 781.5 | T4: {=D4/R4} -> 13.166987 | U4: {=T4-H4} -> -286.83301 | V4: {=S4/D4} -> 22.784257 | W4: 31.53 | X4: 39.3
A5: Portfólio | H5: {=SUM(H3:H4)} -> 700 | J5: {=SUM(J3:J4)} -> 45452 | K5: {=SUM(K3:K4)} -> 39686 | L5: {=SUM(L3:L4)} -> -5766 | M5: {=SUM(M3:M4)} -> 0 | N5: {=(K5-J5)/J5} -> -0.1268591 | O5: {=G3+G4} -> -0.17812823 | Q5: {=SUM(Q3:Q4)} -> 5.21 | R5: {=SUM(R3:R4)} -> 2.605 | S5: {=SUM(S3:S4)} -> 781.5 | T5: {=SUM(T3:T4)} -> 13.166987 | U5: {=SUM(U3:U4)} -> -286.83301 | V5: {=SUM(V3:V4)} -> 22.784257 | W5: {=SUM(W3:W4)} -> 98.45 | X5: {=SUM(X3:X4)} -> 163.1

Sheet AÇÕES - Tabela 3
A1: Tabela 3

Sheet AÇÕES - Comparação de FII
A1: Comparação de FII
A2: FII’S Atuais | C2: FII’s Finclass
A3: MALL11 | C3: VISC11
A4: HGBS11 | C4: PROD11
A5: MXRF11 | C5: XPML11
A6: XPML11 | C6: RVBI11
A7: VISC11 | C7: BTCI11
A8: PROD11 | C8: RBFF11
C9: PVBI11
C10: GARE11
C11: KFOF11
C12: BRCR11
C13: VILG11
C14: CPTS11
C15: KNSC11
C16: LVBI11
C17: JSRE11
C18: RBVA11
C19: PALT11

Sheet AÇÕES - Desenhos

Sheet ETF BRASIL - Visão Geral
A1: Ganho do Portfólio | B1: {='ETF BRASIL - Meu Portfólio'!K$4} -> 31226
A2: Perda/Ganho | B2: {='ETF BRASIL - Meu Portfólio'!L4-'ETF BRASIL - Meu Portfólio'!M4} -> -5096 | C2: {=IF(B2>0,"↑",IF(B2<0,"↓","–"))} -> ↓
A3: % Alteração | B3: {='ETF BRASIL - Meu Portfólio'!O$4} -> -0.14030064 | C3: {=IF(B3="–","–",IF(B3>0,"↑",IF(B3<0,"↓","–")))} -> ↓

Sheet ETF BRASIL - REFERENCIAL
A1: REFERENCIAL
B2: CAIU 10% OU MAIS EM RELAÇÃO AO PREÇO PAGO
B3: CAIU 20% OU MAIS EM RELAÇÃO AO PREÇO PAGO
B4: SUBIU 10% OU MAIS EM RELAÇÃO AO PREÇO PAGO
B5: SUBIU 20% OU MAIS EM RELAÇÃO AO PREÇO PAGO

Sheet ETF BRASIL - Meu Portfólio
A1: 12
A2: Símbolo | B2: Nome | C2: SETOR | D2: Preço | E2: Preço Pago | F2: Alteração de Preço | G2: % Alteração | H2: QTD Cotas | I2: Preço Pago em Dólares Americanos | J2: Quanto paguei | K2: Valor de Mercado | L2: Ganho | M2: Ganho Anterior | N2: % Ganho | P2: Data de PG de Dividendos | Q2: Dividendo anual por ação | R2: Expectativa de pagamento de dividendos por período | S2: Dividendo Recebido | T2: Magic Number | U2: QTD q falta | V2: Com o Dividendo recebido consigo comprar… | W2: Min 52 semanas | X2: Max 52 semanas
A3: COIN11 | B3: ETF BV COIN CI ER | C3: BITCOIN | D3: 48.04 | E3: 55.88 | F3: {=D3-E3} -> -7.84 | G3: {=(D3-E3)/E3} -> -0.14030064 | H3: 650 | I3: 0.20426506 | J3: 36322 | K3: 31226 | L3: {=_xlfn.IFERROR(K3-J3,"–")} -> -5096 | M3: 0 | N3: {=_xlfn.IFERROR((K3-J3)/J3,"–")} -> -0.14030064 | P3: 46090 | S3: {=H3+Q3} | T3: {=D3/Q3} | U3: {=T3-H3} | V3: {=S3/D3} | W3: 42.41 | X3: 97.67
A4: Portfólio | H4: {=SUM(H3:H3)} -> 650 | J4: {=SUM(J3:J3)} -> 36322 | K4: {=SUM(K3:K3)} -> 31226 | L4: {=SUM(L3:L3)} -> -5096 | M4: {=SUM(M3:M3)} -> 0 | N4: {=(K4-J4)/J4} -> -0.14030064 | O4: {=(K$4-J$4)/J$4} -> -0.14030064 | P4: {=SUM(P3:P3)} -> 46090 | Q4: {=SUM(Q3:Q3)} | R4: {=SUM(R3:R3)} -> 0 | S4: {=SUM(S3:S3)} | T4: {=SUM(T3:T3)} | U4: {=SUM(U3:U3)} | V4: {=SUM(V3:V3)} | W4: {=SUM(W3:W3)} -> 42.41 | X4: {=SUM(X3:X3)} -> 97.67

Sheet ETF BRASIL - Tabela 3
A1: Tabela 3

Sheet ETF BRASIL - Desenhos

Sheet ETF USA - Visão Geral
A1: Valor de Mercado | B1: {='ETF USA - Meu Portfólio'!K$10} -> 24349.406
A2: Alteração | B2: {='ETF USA - Meu Portfólio'!L10-'ETF USA - Meu Portfólio'!M10} -> 850.69936 | C2: {=IF(B2>0,"↑",IF(B2<0,"↓","–"))} -> ↑
A3: % Alteração | B3: {='ETF USA - Meu Portfólio'!O$10} -> 0.14426132 | C3: {=IF(B3="–","–",IF(B3>0,"↑",IF(B3<0,"↓","–")))} -> ↑

Sheet ETF USA - REFERENCIAL
A1: REFERENCIAL
B2: CAIU 10% OU MAIS EM RELAÇÃO AO PREÇO PAGO
B3: CAIU 20% OU MAIS EM RELAÇÃO AO PREÇO PAGO
B4: SUBIU 10% OU MAIS EM RELAÇÃO AO PREÇO PAGO
B5: SUBIU 20% OU MAIS EM RELAÇÃO AO PREÇO PAGO

Sheet ETF USA - Meu Portfólio
A2: Símbolo | B2: Nome | C2: SETOR | D2: Preço | E2: Preço Pago | F2: Alteração de Preço | G2: % Alteração | H2: QTD Cotas | I2: Preço Pago em Dólares Americanos | J2: Quanto paguei | K2: Valor de Mercado | L2: Ganho | M2: Ganho Anterior | N2: % Ganho | P2: Data de PG de Dividendos | Q2: Dividendo por ação | R2: Dividendo Recebido | S2: Magic Number | T2: QTD q falta | U2: Com o Dividendo recebido consigo comprar… | V2: Min 52 semanas | W2: Max 52 semanas
A3: TLT | B3: iShares 20+ Year Treasury Bond | C3: RENDA FIXA (US TREASURIES) | D3: 85.65 | E3: 88.08 | F3: {=D3-E3} -> -2.43 | G3: {=(D3-E3)/E3} -> -0.027588556 | H3: 5.677 | I3: 0.20426506 | J3: 2447.9477 | K3: 2380.4123 | L3: {=_xlfn.IFERROR(K3-J3,"–")} -> -67.535341 | M3: -2.415991e-14 | N3: {=_xlfn.IFERROR((K3-J3)/J3,"–")} -> -0.027588556 | P3: 46086 | Q3: 0.3 | R3: 8.3376964 | S3: {=D3/Q3} -> 285.5 | T3: {=S3-H3} -> 279.823 | U3: {=R3/D3} -> 0.097346134 | V3: 83.3 | W3: 92.19
A4: BND | B4: Vanguard Total Bond Market ETF | C4: RENDA FIXA (AGGREGATE) | D4: 73.36 | E4: 74.26 | F4: {=D4-E4} -> -0.9 | G4: {=(D4-E4)/E4} -> -0.01211958 | H4: 6.733 | J4: 2447.7637 | K4: 2418.0978 | L4: {=_xlfn.IFERROR(K4-J4,"–")} -> -29.665867 | P4: 46085 | Q4: 0.22 | R4: 7.2516565 | S4: {=D4/Q4} -> 333.45455 | T4: {=S4-H4} -> 326.72155 | U4: {=R4/D4} -> 0.098850279 | V4: 71.76 | W4: 75.23
A5: IUSB | B5: iShares Core Universal USD Bond | C5: RENDA FIXA (AGGREGATE) | D5: 46.12 | E5: 46.93 | F5: {=D5-E5} -> -0.81 | G5: {=(D5-E5)/E5} -> -0.017259749 | H5: 21.307 | J5: 4895.2941 | K5: 4810.8025 | L5: {=_xlfn.IFERROR(K5-J5,"–")} -> -84.491545 | P5: 46058 | Q5: 0.16 | R5: 16.689688 | S5: {=D5/Q5} -> 288.25 | T5: {=S5-H5} -> 266.943 | U5: {=R5/D5} -> 0.36187528 | V5: 45.07 | W5: 47.23
A6: JCPB | B6: JPMorgan Core Plus Bond ETF | C6: RENDA FIXA (CORE PLUS) | D6: 46.89 | E6: 47.65 | F6: {=D6-E6} -> -0.76 | G6: {=(D6-E6)/E6} -> -0.015949633 | H6: 10.493 | J6: 2447.7581 | K6: 2408.7173 | L6: {=_xlfn.IFERROR(K6-J6,"–")} -> -39.040843 | P6: 46086 | Q6: 0.18 | R6: 9.2465155 | S6: {=D6/Q6} -> 260.5 | T6: {=S6-H6} -> 250.007 | U6: {=R6/D6} -> 0.1971959 | V6: 45.85 | W6: 48.17
A7: IAGG | B7: iShares International Aggregate | C7: RENDA FIXA (INTERNATIONAL) | D7: 50.04 | E7: 50.16 | F7: {=D7-E7} -> -0.12 | G7: {=(D7-E7)/E7} -> -0.0023923445 | H7: 5.981 | J7: 1468.7141 | K7: 1465.2004 | L7: {=_xlfn.IFERROR(K7-J7,"–")} -> -3.51367 | P7: 46058 | Q7: 0.1 | R7: 2.9280584 | S7: {=D7/Q7} -> 500.4 | T7: {=S7-H7} -> 494.419 | U7: {=R7/D7} -> 0.058514356 | V7: 49.645 | W7: 51.83
A8: IBIT | B8: iShares Bitcoin Trust ETF | C8: BITCOIN | D8: 45.4 | E8: 37.16 | F8: {=D8-E8} -> 8.24 | G8: {=(D8-E8)/E8} -> 0.22174381 | H8: 26.911 | J8: 4895.6625 | K8: 5981.2453 | L8: {=_xlfn.IFERROR(K8-J8,"–")} -> 1085.5829 | P8: - | Q8: - | R8: - | S8: - | T8: - | U8: - | V8: 35.3 | W8: 71.82
A9: TFLO | B9: iShares Treasury Floating Rate | C9: RENDA FIXA (FLOATING RATE) | D9: 50.52 | E9: 50.63 | F9: {=D9-E9} -> -0.11 | G9: {=(D9-E9)/E9} -> -0.0021726249 | H9: 19.751 | J9: 4895.5664 | K9: 4884.9301 | L9: {=_xlfn.IFERROR(K9-J9,"–")} -> -10.63623 | P9: 46058 | Q9: 0.15 | R9: 14.503949 | S9: {=D9/Q9} -> 336.8 | T9: {=S9-H9} -> 317.049 | U9: {=R9/D9} -> 0.28709322 | V9: 50.39 | W9: 50.67
A10: Portfólio | H10: {=SUM(H3:H9)} -> 96.853 | J10: {=SUM(J3:J9)} -> 23498.706 | K10: {=SUM(K3:K9)} -> 24349.406 | L10: {=SUM(L3:L9)} -> 850.69936 | M10: {=SUM(M3:M9)} -> -2.415991e-14 | N10: {=(K10-J10)/J10} -> 0.036201965 | O10: {=G3+G4+G5+G6+G7+G8+G9} -> 0.14426132 | Q10: {=SUM(Q3:Q9)} -> 1.11 | R10: {=SUM(R3:R9)} -> 58.957564 | S10: {=SUM(S3:S9)} -> 2004.9045 | T10: {=SUM(T3:T9)} -> 1934.9625 | U10: {=SUM(U3:U9)} -> 1.1008752 | V10: {=SUM(V3:V9)} -> 381.315 | W10: {=SUM(W3:W9)} -> 437.14

Sheet ETF USA - Tabela 1
A1: Tabela 1
A2: 12

Sheet ETF USA - Tabela 2
A1: Tabela 2
A2: Vendas 21/10/2024 | B2: Pagamento do Sigma | F2: RETORNO
A3: Papel | B3: QTD | C3: Valor unitário | D3: Montante final | E3: PREJUÍZO/LUCRO | G3: PAPEL | H3: DATA DA COMPRA | I3: QTD | J3: VALOR UNITÁRIO | K3: MONTANTE FINAL
A4: ITUB3 | B4: 100 | C4: 30.44 | D4: {=C4*B4} -> 3044 | E4: {=C4-#REF!} | K4: {=I4*J4} -> 0
A5: BBAS3 | B5: 93 | C5: 26.9 | D5: {=C5*B5} -> 2501.7 | E5: {=C5-#REF!} | G5: BBAS3 | H5: 45664 | I5: 100 | J5: 24.14 | K5: {=I5*J5} -> 2414
A6: SUZB3 | B6: 32 | C6: 56.42 | D6: {=C6*B6} -> 1805.44 | E6: {=C6-#REF!} | K6: {=I6*J6} -> 0
A7: BRAV3 | B7: 49 | C7: 17.16 | D7: {=C7*B7} -> 840.84 | E7: {=C7-#REF!} | K7: {=I7*J7} -> 0
A8: ENGI3 | B8: 41 | C8: 12.83 | D8: {=C8*B8} -> 526.03 | E8: {=C8-#REF!} | K8: {=I8*J8} -> 0
A9: STBP3 | B9: 151 | C9: 12.94 | D9: {=C9*B9} -> 1953.94 | E9: {=C9-#REF!} | G9: STBP3F | H9: 45601 | I9: 78 | J9: 12.72 | K9: {=I9*J9} -> 992.16
A10: MALL11 | B10: 44 | C10: 100.07 | D10: {=C10*B10} -> 4403.08 | E10: {=C10-99.14} -> 0.93 | J10: 0 | K10: {=I10*J10} -> 0
A11: HGBS11 | B11: 13 | C11: 201.4 | D11: {=C11*B11} -> 2618.2 | E11: {=C11-193} -> 8.4 | J11: 0 | K11: {=I11*J11} -> 0
A12: MXRF11 | B12: 252 | C12: 9.71 | D12: {=C12*B12} -> 2446.92 | E12: {=C12-10.35} -> -0.64 | J12: 0 | K12: {=I12*J12} -> 0
A13: XPML11 | B13: 17 | C13: 105.09 | D13: {=C13*B13} -> 1786.53 | E13: {=C13-102} -> 3.09 | J13: 0 | K13: {=I13*J13} -> 0
A14: VISC11 | B14: 15 | C14: 102.11 | D14: {=C14*B14} -> 1531.65 | E14: {=C14-108} -> -5.89 | G14: VISC11 | H14: 45639 | I14: 5 | J14: 91.72 | K14: {=I14*J14} -> 458.6
D15: {=C15*B15} -> 0 | G15: VISC11 | H15: 45642 | I15: 10 | J15: 91.6 | K15: {=I15*J15} -> 916
D16: {=C16*B16} -> 0 | G16: GGBR3F | H16: 45615 | I16: 42 | J16: 19.12 | K16: {=I16*J16} -> 803.04
D17: {=C17*B17} -> 0 | G17: KEPL3 | H17: 45664 | I17: 200 | J17: 9.2 | K17: {=I17*J17} -> 1840
D18: {=C18*B18} -> 0 | G18: PORD11 | H18: 45639 | I18: 10 | J18: 7.49 | K18: {=I18*J18} -> 74.9
D19: {=C19*B19} -> 0 | H19: 45663 | I19: 51 | J19: 7.72 | K19: {=I19*J19} -> 393.72
D20: {=C20*B20} -> 0 | H20: 45664 | I20: 100 | J20: 7.72 | K20: {=I20*J20} -> 772
D21: {=C21*B21} -> 0 | G21: CPTS11 | H21: 45663 | I21: 56 | J21: 6.82 | K21: {=I21*J21} -> 381.92
D22: {=C22*B22} -> 0 | H22: 45664 | I22: 200 | J22: 6.7 | K22: {=I22*J22} -> 1340
D23: {=C23*B23} -> 0 | G23: Prefixado 2031 | H23: 45663 | I23: 435.69 | J23: 4.59 | K23: {=I23*J23} -> 1999.8171
D24: {=C24*B24} -> 0 | G24: SELIC 2029 | H24: 45663 | I24: 2.58 | J24: 15763.63 | K24: {=J24/I24} -> 6109.9341
D25: {=C25*B25} -> 0 | G25: XRP | H25: 45664 | I25: 0.055422 | J25: 166 | K25: 166
D26: {=C26*B26} -> 0 | G26: ETH | H26: 45664 | I26: 3.242e-05 | J26: 166 | K26: 166
D27: {=C27*B27} -> 0 | G27: SOL | H27: 45664 | I27: 8.212e-05 | J27: 166 | K27: 166
D28: {=C28*B28} -> 0 | G28: BTC | H28: 45664 | I28: 7.1e-07 | J28: 100 | K28: 100
D29: {=C29*B29} -> 0 | G29: NEAR | H29: 45664 | I29: 4.9917048 | J29: 166 | K29: 166
D30: {=C30*B30} -> 0 | G30: SNX | H30: 45664 | I30: 13.823661 | J30: 166 | K30: 166
D31: {=C31*B31} -> 0 | G31: DOG | H31: 45664 | I31: 4416.579 | J31: 166 | K31: 166
D32: {=C32*B32} -> 0 | G32: BTCI11 | H32: 45664 | I32: 70 | J32: 8.89 | K32: {=I32*J32} -> 622.3
A33: TOTAL | B33: {=SUM(D4:D14)} -> 23458.33 | K33: {=SUM(K4:K32)} -> 20214.391

Sheet ETF USA - Tabela 3
A1: Tabela 3

Sheet ETF USA - Comparação de FII
A1: Comparação de FII
A2: FII’S Atuais | C2: FII’s Finclass
A3: MALL11 | C3: VISC11
A4: HGBS11 | C4: PROD11
A5: MXRF11 | C5: XPML11
A6: XPML11 | C6: RVBI11
A7: VISC11 | C7: BTCI11
A8: PROD11 | C8: RBFF11
C9: PVBI11
C10: GARE11
C11: KFOF11
C12: BRCR11
C13: VILG11
C14: CPTS11
C15: KNSC11
C16: LVBI11
C17: JSRE11
C18: RBVA11
C19: PALT11

Sheet ETF USA - Desenhos

Sheet Fundos Imobiliários - Visão Ger
A1: Valor de Mercado | B1: {='Fundos Imobiliários - Meu Portf'!K$6} -> 29988.78
A2: Perda/Ganho | B2: {='Fundos Imobiliários - Meu Portf'!L6-'Fundos Imobiliários - Meu Portf'!M6} -> 2459.87 | C2: {=IF(B2>0,"↑",IF(B2<0,"↓","–"))} -> ↑
A3: % Alteração | B3: {='Fundos Imobiliários - Meu Portf'!O$6} -> 0.19134071 | C3: {=IF(B3="–","–",IF(B3>0,"↑",IF(B3<0,"↓","–")))} -> ↑

Sheet Fundos Imobiliários - REFERENCI
A1: REFERENCIAL
B2: CAIU 10% OU MAIS EM RELAÇÃO AO PREÇO PAGO
B3: CAIU 20% OU MAIS EM RELAÇÃO AO PREÇO PAGO
B4: SUBIU 10% OU MAIS EM RELAÇÃO AO PREÇO PAGO
B5: SUBIU 20% OU MAIS EM RELAÇÃO AO PREÇO PAGO

Sheet Fundos Imobiliários - Meu Portf
A2: Símbolo | B2: Nome | C2: SETOR | D2: Preço | E2: Preço Pago | F2: Alteração de Preço | G2: % Alteração | H2: QTD Cotas | I2: Preço Pago em Dólares Americanos | J2: Quanto paguei | K2: Valor de Mercado | L2: Ganho | M2: Ganho Anterior | N2: % Ganho | P2: Data de PG de Dividendos | Q2: Dividendo Anual por ação | R2: Expectativa de pagamento de dividendos por período | S2: Dividendo Recebido Mensalmente | T2: Expectativa Dividendo Recebido Anualmente | U2: Magic Number | V2: QTD q falta | W2: Com o Dividendo recebido mensalmente consigo comprar… | X2: Min 52 semanas | Y2: Max 52 semanas
A3: MCCI11 | B3: FII MAUA CI | C3: FUNDO DE PAPEL | D3: 96.24 | E3: 92.15 | F3: {=D3-E3} -> 4.09 | G3: {=(D3-E3)/E3} -> 0.044384156 | H3: 169 | I3: 0.20426506 | J3: 15573.35 | K3: 16264.56 | L3: {=_xlfn.IFERROR(K3-J3,"–")} -> 691.21 | M3: 0 | N3: {=_xlfn.IFERROR((K3-J3)/J3,"–")} -> 0.044384156 | P3: 46073 | Q3: 12 | R3: 1 | S3: 169 | T3: {=S3*12} -> 2028 | U3: {=D3/R3} -> 96.24 | V3: {=U3-H3} -> -72.76 | W3: {=S3/D3} -> 1.7560266 | X3: 83.65 | Y3: 97.58
A4: PCIP11 | B4: FII PCIP PAXCI | C4: FUNDO DE PAPEL | D4: 86.14 | E4: 74.28 | F4: {=D4-E4} -> 11.86 | G4: {=(D4-E4)/E4} -> 0.15966613 | H4: 150 | J4: 11142 | K4: 12921 | L4: {=_xlfn.IFERROR(K4-J4,"–")} -> 1779 | P4: 46071 | Q4: 10.2 | R4: 0.85 | S4: 127.5 | T4: {=S4*12} -> 1530 | U4: {=D4/R4} -> 101.34118 | V4: {=U4-H4} -> -48.658824 | W4: {=S4/D4} -> 1.4801486 | X4: 77.54 | Y4: 89.85
A5: CXCI11 | B5: FII CAIXA CICI | C5: FUNDOS DE FUNDOS (FOF) | D5: 73.02 | E5: 73.96 | F5: {=D5-E5} -> -0.94 | G5: {=(D5-E5)/E5} -> -0.012709573 | H5: 11 | J5: 813.56 | K5: 803.22 | L5: {=_xlfn.IFERROR(K5-J5,"–")} -> -10.34 | P5: 46066 | Q5: 9 | R5: 0.75 | S5: 8.25 | T5: {=S5*12} -> 99 | U5: {=D5/R5} -> 97.36 | V5: {=U5-H5} -> 86.36 | W5: {=S5/D5} -> 0.11298274 | X5: 63.5 | Y5: 77.01
A6: Portfólio | H6: {=SUM(H3:H5)} -> 330 | J6: {=SUM(J3:J5)} -> 27528.91 | K6: {=SUM(K3:K5)} -> 29988.78 | L6: {=SUM(L3:L5)} -> 2459.87 | M6: {=SUM(M3:M5)} -> 0 | N6: {=(K6-J6)/J6} -> 0.089355881 | O6: {=SUM(G3:G5)} -> 0.19134071 | Q6: {=SUM(Q3:Q5)} -> 31.2 | R6: {=SUM(R3:R5)} -> 2.6 | S6: {=SUM(S3:S5)} -> 304.75 | T6: {=SUM(T3:T5)} -> 3657 | U6: {=SUM(U3:U5)} -> 294.94118 | V6: {=SUM(V3:V5)} -> -35.058824 | W6: {=SUM(W3:W5)} -> 3.3491579 | X6: {=SUM(X3:X5)} -> 224.69 | Y6: {=SUM(Y3:Y5)} -> 264.44

Sheet Fundos Imobiliários - Tabela 1
A1: Tabela 1
A2: 12

Sheet Fundos Imobiliários - Tabela 3
A1: Tabela 3

Sheet Fundos Imobiliários - Desenhos

Sheet Reit's - Visão Geral
A1: Valor de Mercado | B1: {='Reit''s - Meu Portfólio'!K$6} -> 7902.2825
A2: Perda/Ganho | B2: {='Reit''s - Meu Portfólio'!L6-'Reit''s - Meu Portfólio'!M6} -> 558.85776 | C2: {=IF(B2>0,"↑",IF(B2<0,"↓","–"))} -> ↑
A3: % Alteração | B3: {='Reit''s - Meu Portfólio'!O$6} -> 0.22830522 | C3: {=IF(B3="–","–",IF(B3>0,"↑",IF(B3<0,"↓","–")))} -> ↑

Sheet Reit's - REFERENCIAL
A1: REFERENCIAL
B2: CAIU 10% OU MAIS EM RELAÇÃO AO PREÇO PAGO
B3: CAIU 20% OU MAIS EM RELAÇÃO AO PREÇO PAGO
B4: SUBIU 10% OU MAIS EM RELAÇÃO AO PREÇO PAGO
B5: SUBIU 20% OU MAIS EM RELAÇÃO AO PREÇO PAGO

Sheet Reit's - Meu Portfólio
A2: Símbolo | B2: Nome | C2: SETOR | D2: Preço | E2: Preço Pago | F2: Alteração de Preço | G2: % Alteração | H2: QTD Cotas | I2: Preço Pago em Dólares Americanos | J2: Quanto paguei | K2: Valor de Mercado | L2: Ganho | M2: Ganho Anterior | N2: % Ganho | P2: Data de PG de Dividendos | Q2: Dividendo Anual por ação | R2: Expectativa de pagamento de dividendos por período | S2: Dividendo Recebido por período em reais | T2: Expectativa Dividendo Recebido Anualmente | U2: Magic Number | V2: QTD q falta | W2: Com o Dividendo recebido consigo comprar… | X2: Min 52 semanas | Y2: Max 52 semanas
A3: PSA | B3: Public Storage | C3: SELF STORAGE | D3: 309.33 | E3: 262.2 | F3: {=D3-E3} -> 47.13 | G3: {=(D3-E3)/E3} -> 0.17974828 | H3: 1.907 | I3: 0.20426506 | J3: 2447.8754 | K3: 2887.8768 | L3: {=_xlfn.IFERROR(K3-J3,"–")} -> 440.0014 | M3: -2.4159197e-14 | N3: {=_xlfn.IFERROR((K3-J3)/J3,"–")} -> 0.17974828 | P3: 46112 | Q3: 12 | R3: 3 | S3: 28.007728 | T3: {=S3*4} -> 112.03091 | U3: {=D3/R3} -> 103.11 | V3: {=U3-H3} -> 101.203 | W3: {=S3/D3} -> 0.090543199 | X3: 256.54 | Y3: 313.51
A4: VICI | B4: VICI Properties Inc. | C4: GAMING/LEISURE | D4: 28.79 | E4: 28.05 | F4: {=D4-E4} -> 0.74 | G4: {=(D4-E4)/E4} -> 0.026381462 | H4: 17.825 | J4: 2447.7572 | K4: 2512.3326 | L4: {=_xlfn.IFERROR(K4-J4,"–")} -> 64.575412 | P4: 46030 | Q4: 1.78 | R4: 0.445 | S4: 38.832511 | T4: {=S4*4} -> 155.33004 | U4: {=D4/R4} -> 64.696629 | V4: {=U4-H4} -> 46.871629 | W4: {=S4/D4} -> 1.3488194 | X4: 26.55 | Y4: 34.01
A5: AMT | B5: American Tower Corporation (REI | C5: TELECOM TOWERS | D5: 179.77 | E5: 175.87 | F5: {=D5-E5} -> 3.9 | G5: {=(D5-E5)/E5} -> 0.022175471 | H5: 2.843 | J5: 2447.7922 | K5: 2502.0732 | L5: {=_xlfn.IFERROR(K5-J5,"–")} -> 54.280944 | P5: 46055 | Q5: 6.89 | R5: 1.7225 | S5: 23.974084 | T5: {=S5*4} -> 95.896335 | U5: {=D5/R5} -> 104.36575 | V5: {=U5-H5} -> 101.52275 | W5: {=S5/D5} -> 0.13335976 | X5: 165.08 | Y5: 234.33
A6: Portfólio | H6: {=SUM(H3:H5)} -> 22.575 | J6: {=SUM(J3:J5)} -> 7343.4248 | K6: {=SUM(K3:K5)} -> 7902.2825 | L6: {=SUM(L3:L5)} -> 558.85776 | M6: {=SUM(M3:M5)} -> -2.4159197e-14 | N6: {=(K6-J6)/J6} -> 0.07610315 | O6: {=SUM(G3:G5)} -> 0.22830522 | Q6: {=SUM(Q3:Q5)} -> 20.67 | R6: {=SUM(R3:R5)} -> 5.1675 | S6: {=SUM(S3:S5)} -> 90.814322 | T6: {=SUM(T3:T5)} -> 363.25729 | U6: {=SUM(U3:U5)} -> 272.17238 | V6: {=SUM(V3:V5)} -> 249.59738 | W6: {=SUM(W3:W5)} -> 1.5727224 | X6: {=SUM(X3:X5)} -> 448.17 | Y6: {=SUM(Y3:Y5)} -> 581.85

Sheet Reit's - Tabela 1
A1: Tabela 1
A2: 12

Sheet Reit's - Tabela 3
A1: Tabela 3

Sheet Reit's - Desenhos

Sheet STOCKS - Visão Geral
A1: Valor Total de Mercado | B1: {='STOCKS - Meu Portfólio'!D3} -> 337.46
A2: Perda/Ganho | B2: {='STOCKS - Meu Portfólio'!L4-'STOCKS - Meu Portfólio'!M4} -> -383.25988 | C2: {=IF(B2>0,"↑",IF(B2<0,"↓","–"))} -> ↓
A3: % Alteração | B3: {='STOCKS - Meu Portfólio'!O$4} -> -0.10440552 | C3: {=IF(B3="–","–",IF(B3>0,"↑",IF(B3<0,"↓","–")))} -> ↓

Sheet STOCKS - REFERENCIAL
A1: REFERENCIAL
B2: CAIU 10% OU MAIS EM RELAÇÃO AO PREÇO PAGO
B3: CAIU 20% OU MAIS EM RELAÇÃO AO PREÇO PAGO
B4: SUBIU 10% OU MAIS EM RELAÇÃO AO PREÇO PAGO
B5: SUBIU 20% OU MAIS EM RELAÇÃO AO PREÇO PAGO

Sheet STOCKS - Meu Portfólio
A2: Símbolo | B2: Nome | C2: SETOR | D2: Preço | E2: Preço Pago | F2: Alteração de Preço | G2: % Alteração | H2: QTD Cotas | I2: Preço Pago em Dólares Americanos | J2: Quanto paguei | K2: Valor de Mercado | L2: Ganho | M2: Ganho Anterior | N2: % Ganho | P2: Data de PG de Dividendos | Q2: Dividendo por ação | R2: Dividendo Recebido | S2: Magic Number | T2: QTD q falta | U2: Com o Dividendo recebido consigo comprar… | V2: Min 52 semanas | W2: Max 52 semanas
A3: RACE | B3: Ferrari N.V. | C3: LUXURY AUTOMOTIVE | D3: 337.46 | E3: 376.8 | F3: {=D3-E3} -> -39.34 | G3: {=(D3-E3)/E3} -> -0.10440552 | H3: 1.99 | I3: 0.20426506 | J3: 3670.8775 | K3: 3287.6177 | L3: {=_xlfn.IFERROR(K3-J3,"–")} -> -383.25988 | M3: -3.6229562e-14 | N3: {=_xlfn.IFERROR((K3-J3)/J3,"–")} -> -0.10440552 | P3: 46147 | Q3: 4.23 | R3: 48.518781 | S3: {=D3/Q3} -> 79.777778 | T3: {=S3-H3} -> 77.787778 | U3: {=R3/D3} -> 0.14377639 | V3: 312.51 | W3: 519.1
A4: Portfólio | H4: {=SUM(H3:H3)} -> 1.99 | J4: {=SUM(J3:J3)} -> 3670.8775 | K4: {=SUM(K3:K3)} -> 3287.6177 | L4: {=SUM(L3:L3)} -> -383.25988 | M4: {=SUM(M3:M3)} -> -3.6229562e-14 | N4: {=(K4-J4)/J4} -> -0.10440552 | O4: {=(K$4-J$4)/J$4} -> -0.10440552 | Q4: {=SUM(Q3:Q3)} -> 4.23 | R4: {=SUM(R3:R3)} -> 48.518781 | S4: {=SUM(S3:S3)} -> 79.777778 | T4: {=SUM(T3:T3)} -> 77.787778 | U4: {=SUM(U3:U3)} -> 0.14377639 | V4: {=SUM(V3:V3)} -> 312.51 | W4: {=SUM(W3:W3)} -> 519.1

Sheet STOCKS - Tabela 1
A1: Tabela 1
A2: 12

Sheet STOCKS - Tabela 3
A1: Tabela 3

Sheet STOCKS - Desenhos

Sheet CDB - Visão Geral
A1: Valor Total de Mercado | B1: {='CDB - Meu Portfólio'!R6+'CDB - Meu Portfólio-1'!K6} -> 2157.0644
A2: Ganhos/Perdas | B2: {='CDB - Meu Portfólio'!S6+'CDB - Meu Portfólio-1'!R6} -> 92.614433 | C2: {=IF(B2>0,"↑",IF(B2<0,"↓","–"))} -> ↑
A3: % Alteração | B3: {='CDB - Meu Portfólio'!T6+'CDB - Meu Portfólio-1'!N6} -> 0.089752693 | C3: {=IF(B3="–","–",IF(B3>0,"↑",IF(B3<0,"↓","–")))} -> ↑

Sheet CDB - REFERENCIAL
A1: REFERENCIAL
B2: CAIU 10% OU MAIS EM RELAÇÃO AO PREÇO PAGO
B3: CAIU 20% OU MAIS EM RELAÇÃO AO PREÇO PAGO
B4: SUBIU 10% OU MAIS EM RELAÇÃO AO PREÇO PAGO
B5: SUBIU 20% OU MAIS EM RELAÇÃO AO PREÇO PAGO

Sheet CDB - Meu Portfólio
A2: Símbolo | B2: Nome | C2: Data da Aplicação | D2: Data do Vencimento | E2: Taxa | F2: Preço | G2: Preço Pago | H2: Alteração de Preço | I2: QTD Cotas | J2: Preço Pago em Dólares Americanos | K2: Quanto paguei | L2: Ganho Anterior | M2: % Ganho | N2: Mês | O2: CDI mensal | P2: Fator mensal | Q2: Fator acumulado | R2: Valor Atual estimado | S2: Ganhos | T2: Rentabilidade acumulada | U2: CDI Acumulado | V2: Diferença
A3: CDB - 1 | B3: CDB XP - JAN/28 | C3: 46027 | D3: 46757 | E3: 100% CDI | F3: 1.03018 | G3: 1 | H3: {=F3-G3} -> 0.03018 | I3: 1000 | J3: 0.20426506 | K3: 1000 | L3: 0 | M3: {=_xlfn.IFERROR((#REF!-K3)/K3,"–")} -> – | N3: 46023 | O3: 0.0116 | P3: {=1+O3} -> 1.0116 | Q3: {=P3} -> 1.0116 | R3: {=K3*Q3} -> 1011.6 | S3: {=R3-K3} -> 11.6 | T3: {=(R3/K3)-1} -> 0.0116 | U3: {=Q3-1} -> 0.0116 | V3: {=T3-U3} -> 0
N4: 46054 | O4: 0.01 | P4: {=1+O4} -> 1.01 | Q4: {=Q3*P4} -> 1.021716 | R4: {=K3*Q4} -> 1021.716 | S4: {=R4-K3} -> 21.716 | T4: {=(R4/K3)-1} -> 0.021716 | U4: {=Q4-1} -> 0.021716 | V4: {=T4-U4} -> 0
N5: 46082 | O5: 0.0121 | P5: {=1+O5} -> 1.0121 | Q5: {=Q4*P5} -> 1.0340788 | R5: {=K3*Q5} -> 1034.0788 | S5: {=R5-K3} -> 34.078764 | T5: {=(R5/K3)-1} -> 0.034078764 | U5: {=Q5-1} -> 0.034078764 | V5: {=T5-U5} -> 0
N6: 46113 | O6: 0.0109 | P6: {=1+O6} -> 1.0109 | Q6: {=Q5*P6} -> 1.0453502 | R6: {=K3*Q6} -> 1045.3502 | S6: {=R6-K3} -> 45.350222 | T6: {=(R6/K3)-1} -> 0.045350222 | U6: {=Q6-1} -> 0.045350222 | V6: {=T6-U6} -> 0
N7: 46143
N8: 46174
N9: 46204
N10: 46235
N11: 46266
N12: 46296
N13: 46327
N14: 46357
N15: 46388
N16: 46419
N17: 46447
N18: 46478
... N27: 46753
A28: Portfólio | I28: {=SUM(I3:I27)} -> 1000 | K28: {=SUM(K3:K27)} -> 1000 | L28: {=SUM(L3:L27)} -> 0 | M28: {=(#REF!-K28)/K28} | P28: {=#REF!+#REF!} | Q28: {=SUM(Q3:Q27)} -> 4.112745 | R28: {=SUM(R3:R27)} -> 4112.745 | S28: {=SUM(S3:S27)} -> 112.74499 | T28: {=SUM(T3:T27)} -> 0.11274499 | U28: {=SUM(U3:U27)} -> 0.11274499 | V28: {=SUM(V3:V27)} -> 0

Sheet CDB - Meu Portfólio-1
I1: {=(1+F3)^(1/12)} -> 1.0110527
A2: Símbolo | B2: Nome | C2: Data da Aplicação | D2: Data do Vencimento | E2: Dia úteis | F2: Taxa | G2: Fator | H2: Mês | I2: Fator mensal | J2: Fator acumulado | K2: Rendimento mensal | L2: Preço | M2: Preço Pago | N2: % Alteração | O2: QTD Cotas | P2: Preço Pago em Dólares Americanos | Q2: Quanto paguei | R2: Ganho | S2: Ganho Anterior | T2: % Ganho
A3: CDB - 2 | B3: CDB XP - AGO/26 | C3: 46027 | D3: 46246 | E3: {=NETWORKDAYS(C3,D3,'CDB - Feriados'!B3:B10)} -> 154 | F3: 0.141 | G3: {=(1+F3)^(E3/252)} -> 1.0839466 | H3: 46023 | I3: {=(1+F3)^(20/252)} -> 1.0105236 | J3: {=(1+F3)^(20/252)} -> 1.0105236 | K3: {=M3*J3} -> 1075.6519 | L3: 1094.97 | M3: 1064.45 | N3: {=(K3-M3)/M3} -> 0.010523645 | O3: 1 | Q3: 1064.45 | R3: {=K3-Q3} -> 11.201893
C4: 46053 | H4: 46054 | I4: {=I$1} -> 1.0110527 | J4: {=J3*I4} -> 1.0216927 | K4: {=M3*J4} -> 1087.5408 | N4: {=(K4-M3)/M3} -> 0.021692684 | R4: {=K4-Q3} -> 23.090777
H5: 46082 | I5: {=I$1} -> 1.0110527 | J5: {=J4*I5} -> 1.0329852 | K5: {=M3*J5} -> 1099.5611 | N5: {=(K5-M3)/M3} -> 0.032985171 | R5: {=K5-Q3} -> 35.111065
H6: 46113 | I6: {=I$1} -> 1.0110527 | J6: {=J5*I6} -> 1.0444025 | K6: {=M3*J6} -> 1111.7142 | N6: {=(K6-M3)/M3} -> 0.044402471 | R6: {=K6-Q3} -> 47.264211
H7: 46143 | I7: {=I$1} -> 1.0110527 | J7: {=J6*I7} -> 1.055946 | K7: {=M3*J7} -> 1124.0017 | R7: {=K7-Q3} -> 59.551681
H8: 46174 | I8: {=I$1} -> 1.0110527 | J8: {=J7*I8} -> 1.067617 | K8: {=M3*J8} -> 1136.425 | R8: {=K8-Q3} -> 71.974962
H9: 46204 | I9: {=I$1} -> 1.0110527 | J9: {=J8*I9} -> 1.0794171 | K9: {=M3*J9} -> 1148.9856 | R9: {=K9-Q3} -> 84.535554
H10: 46235 | I10: {=(1+F3)^(8/252)} -> 1.0041962 | J10: {=J9*I10} -> 1.0839466 | K10: {=M3*J10} -> 1153.807 | R10: {=K10-Q3} -> 89.356975
A11: Portfólio | O11: {=SUM(O3:O10)} -> 1 | Q11: {=SUM(Q3:Q10)} -> 1064.45 | S11: {=SUM(S3:S10)} -> 0 | T11: {=(#REF!-Q11)/Q11}

Sheet CDB - Feriados
A1: Feriados
A4: Confraternização Universal | B4: 46023
A5: Carnaval | B5: 16/02/1026
A6: Carnaval | B6: 17/02/1026
A7: Paixão de Cristo | B7: 46115
A8: Tiradentes | B8: 46133
A9: Dia do trabalho | B9: 46143
A10: Corpus Christi | B10: 46177

Sheet CDB - Tabela 3
A1: Tabela 3

Sheet CDB - Tabela 1
A1: Tabela 1
A2: 12

Sheet CDB - Desenhos

Sheet CRI_CRA - Visão Geral
A1: Valor Total de Mercado | B1: {='CRI_CRA - Meu Portfólio'!K3+#REF!+#REF!+#REF!}
A2: Perdas e Ganhos | B2: {='CRI_CRA - Meu Portfólio'!S18-'CRI_CRA - Meu Portfólio'!T18} -> 4392.57 | C2: {=IF(B2>0,"↑",IF(B2<0,"↓","–"))} -> ↑
A3: % Alteração | B3: {='CRI_CRA - Meu Portfólio'!V$18} | C3: {=IF(B3="–","–",IF(B3>0,"↑",IF(B3<0,"↓","–")))}

Sheet CRI_CRA - REFERENCIAL
A1: REFERENCIAL
B2: CAIU 10% OU MAIS EM RELAÇÃO AO PREÇO PAGO
B3: CAIU 20% OU MAIS EM RELAÇÃO AO PREÇO PAGO
B4: SUBIU 10% OU MAIS EM RELAÇÃO AO PREÇO PAGO
B5: SUBIU 20% OU MAIS EM RELAÇÃO AO PREÇO PAGO

Sheet CRI_CRA - Meu Portfólio
A2: Símbolo | B2: Nome | C2: Data da Aplicação | D2: Data do vencimento | E2: Taxa praticada | F2: Mês | G2: IPCA Mensal | H2: Fator IPCA | I2: Fatos acumulado IPCA | J2: 9,34% | K2: Preço | L2: Preço Pago | M2: Alteração de Preço | N2: % Alteração | O2: QTD Cotas | P2: Preço Pago em Dólares Americanos | Q2: Quanto paguei | R2: Valor de Mercado | S2: Ganho | T2: Ganho Anterior | U2: % Ganho | W2: Min 52 semanas | X2: Max 52 semanas
A3: CRA - 1 | B3: AÇO VERDE - JUN/29 | C3: 44858 | D3: 47284 | E3: IPCA + 9,34% | F3: 10/0022 | G3: 0.0059 | H3: {=1+G3} -> 1.0059 | I3: {=1+G3} -> 1.0059 | J3: {=(1+0.0934)^(6/252)} -> 1.0021283 | K3: 1141.28 | L3: 1028.65 | M3: {=K3-L3} -> 112.63 | N3: {=(K3-L3)/L3} -> 0.10949302 | O3: 39 | P3: 0.20426506 | Q3: 40117.35 | R3: 44509.92 | S3: {=_xlfn.IFERROR(R3-Q3,"–")} -> 4392.57 | T3: 0 | U3: {=_xlfn.IFERROR((R3-Q3)/Q3,"–")} -> 0.10949302 | W3: 312.51 | X3: 519.1
C4: 44866 | D4: 44895 | F4: 11/0022 | G4: 0.0041 | H4: {=1+G4} -> 1.0041 | I4: {=I3*H4} -> 1.0100242 | J4: {=(1+0.0934)^(NETWORKDAYS(C4,D4,'CRI_CRA - Feriado'!B3:B11)/252)} -> 1.0071118
C5: 44896 | D5: 44926 | F5: 12/0022 | G5: 0.0062 | H5: {=1+G5} -> 1.0062 | I5: {=I4*H5} -> 1.0162863 | J5: {=(1+0.0934)^(NETWORKDAYS(C5,D5,'CRI_CRA - Feriado'!C3:C11)/252)} -> 1.0078258
F6: 1/0023 | G6: 0.0053 | H6: {=1+G6} -> 1.0053 | I6: {=I5*H6} -> 1.0216727 | J6: {=(1+0.0934)^(6/252)} -> 1.0021283
F7: 2/0023 | G7: 0.0084 | H7: {=1+G7} -> 1.0084 | I7: {=I6*H7} -> 1.0302547 | J7: {=(1+0.0934)^(6/252)} -> 1.0021283
F8: 3/0023 | G8: 0.0071 | H8: {=1+G8} -> 1.0071 | I8: {=I7*H8} -> 1.0375695 | J8: {=(1+0.0934)^(6/252)} -> 1.0021283
F9: 4/0023 | G9: 0.0061 | H9: {=1+G9} -> 1.0061 | I9: {=I8*H9} -> 1.0438987 | J9: {=(1+0.0934)^(6/252)} -> 1.0021283
F10: 5/0023 | G10: 0.0023 | H10: {=1+G10} -> 1.0023 | I10: {=I9*H10} -> 1.0462997 | J10: {=(1+0.0934)^(6/252)} -> 1.0021283
F11: 6/0023 | G11: -0.0008 | H11: {=1+G11} -> 0.9992 | I11: {=I10*H11} -> 1.0454626 | J11: {=(1+0.0934)^(6/252)} -> 1.0021283
F12: 7/0023 | G12: 0.0012 | H12: {=1+G12} -> 1.0012 | I12: {=I11*H12} -> 1.0467172 | J12: {=(1+0.0934)^(6/252)} -> 1.0021283
F13: 8/0023 | G13: 0.0023 | H13: {=1+G13} -> 1.0023 | I13: {=I12*H13} -> 1.0491246 | J13: {=(1+0.0934)^(6/252)} -> 1.0021283
F14: 9/0023 | G14: 0.0026 | H14: {=1+G14} -> 1.0026 | I14: {=I13*H14} -> 1.0518523 | J14: {=(1+0.0934)^(6/252)} -> 1.0021283
F15: 10/0023 | G15: 0.0024 | H15: {=1+G15} -> 1.0024 | I15: {=I14*H15} -> 1.0543768 | J15: {=(1+0.0934)^(6/252)} -> 1.0021283
F16: 11/0023 | G16: 0.0028 | H16: {=1+G16} -> 1.0028 | I16: {=I15*H16} -> 1.057329 | J16: {=(1+0.0934)^(6/252)} -> 1.0021283
F17: 12/0023 | G17: 0.0056 | H17: {=1+G17} -> 1.0056 | I17: {=I16*H17} -> 1.0632501 | J17: {=(1+0.0934)^(6/252)} -> 1.0021283
A18: Portfólio | O18: {=SUM(O3:O17)} -> 39 | Q18: {=SUM(Q3:Q17)} -> 40117.35 | R18: {=SUM(R3:R17)} -> 44509.92 | S18: {=SUM(S3:S17)} -> 4392.57 | T18: {=SUM(T3:T17)} -> 0 | U18: {=(R18-Q18)/Q18} -> 0.10949302 | V18: {=N3+#REF!+#REF!+#REF!} | W18: {=SUM(W3:W17)} -> 312.51 | X18: {=SUM(X3:X17)} -> 519.1

Sheet CRI_CRA - Meu Portfólio-1
A2: Símbolo | B2: Nome | C2: Data da Aplicação | D2: Data do vencimento | E2: SETOR | F2: Preço | G2: Preço Pago | H2: Alteração de Preço | I2: % Alteração | J2: QTD Cotas | K2: Preço Pago em Dólares Americanos | L2: Quanto paguei | M2: Valor de Mercado | N2: Ganho | O2: Ganho Anterior | P2: % Ganho | R2: Min 52 semanas | S2: Max 52 semanas
A3: CRA - 1 | B3: AÇO VERDE - JUN/29 | C3: 44858 | D3: 47284 | E3: IPCA + 9,34% | F3: 1141.28 | G3: 1028.65 | H3: {=F3-G3} -> 112.63 | I3: {=(F3-G3)/G3} -> 0.10949302 | J3: 39 | K3: 0.20426506 | L3: 40117.35 | M3: 44509.92 | N3: {=_xlfn.IFERROR(M3-L3,"–")} -> 4392.57 | O3: 0 | P3: {=_xlfn.IFERROR((M3-L3)/L3,"–")} -> 0.10949302 | R3: 312.51 | S3: 519.1
A4: CRA - 2 | B4: BTG PACTUAL - NOV/33 | E4: Pré - 12,56% | F4: 86506.1 | G4: 84000 | H4: {=F4-G4} -> 2506.1 | I4: {=(F4-G4)/G4} -> 0.029834524 | J4: 1 | L4: 84000 | M4: 86506.1 | N4: {=_xlfn.IFERROR(M4-L4,"–")} -> 2506.1
A5: CRI - 1 | B5: MATEUS SUP JUL/34 | C5: 44858 | D5: 49142 | E5: IPCA + 9,32% | F5: 874.86 | G5: 975.07 | H5: {=F5-G5} -> -100.21 | I5: {=(F5-G5)/G5} -> -0.10277211 | J5: 42 | L5: 40952.94 | M5: 36744.12 | N5: {=_xlfn.IFERROR(M5-L5,"–")} -> -4208.82
A6: CRI - 2 | B6: SÃO CARLOS SET/29 | C6: 44858 | D6: 47378 | E6: IPCA + 9,57% | F6: 1117.04 | G6: 1019.18 | H6: {=F6-G6} -> 97.86 | I6: {=(F6-G6)/G6} -> 0.096018368 | J6: 40 | L6: 40767.2 | M6: 44681.6 | N6: {=_xlfn.IFERROR(M6-L6,"–")} -> 3914.4
A7: Portfólio | J7: {=SUM(J3:J6)} -> 122 | L7: {=SUM(L3:L6)} -> 205837.49 | M7: {=SUM(M3:M6)} -> 212441.74 | N7: {=SUM(N3:N6)} -> 6604.25 | O7: {=SUM(O3:O6)} -> 0 | P7: {=(M7-L7)/L7} -> 0.032084777 | Q7: {=I3+I4+I5+I6} -> 0.13257381 | R7: {=SUM(R3:R6)} -> 312.51 | S7: {=SUM(S3:S6)} -> 519.1

Sheet CRI_CRA - Feriado
A1: Feriado
A5: Finados | B5: 44867 | C5: 44920
A6: Proclamação da República | B6: 44880

Sheet CRI_CRA - Tabela 1
A1: Tabela 1
A2: 12

Sheet CRI_CRA - Tabela 3
A1: Tabela 3

Sheet CRI_CRA - Desenhos

Sheet FUNDOS - Visão Geral
A1: Valor Total de Mercado | B1: {='FUNDOS - Meu Portfólio'!E3+'FUNDOS - Meu Portfólio'!E4} -> 261210.93
A2: Perda/Ganho | B2: {='FUNDOS - Meu Portfólio'!M6-'FUNDOS - Meu Portfólio'!N6} -> 4943.32 | C2: {=IF(B2>0,"↑",IF(B2<0,"↓","–"))} -> ↑
A3: % Alteração | B3: {='FUNDOS - Meu Portfólio'!P$6} -> 0.046897324 | C3: {=IF(B3="–","–",IF(B3>0,"↑",IF(B3<0,"↓","–")))} -> ↑

Sheet FUNDOS - REFERENCIAL
A1: REFERENCIAL
B2: CAIU 10% OU MAIS EM RELAÇÃO AO PREÇO PAGO
B3: CAIU 20% OU MAIS EM RELAÇÃO AO PREÇO PAGO
B4: SUBIU 10% OU MAIS EM RELAÇÃO AO PREÇO PAGO
B5: SUBIU 20% OU MAIS EM RELAÇÃO AO PREÇO PAGO

Sheet FUNDOS - Meu Portfólio
A2: Símbolo | B2: Nome | C2: SETOR | D2: Resgate | E2: Preço | F2: Preço Pago | G2: Alteração de Preço | H2: % Alteração | I2: QTD Cotas | J2: Preço Pago em Dólares Americanos | K2: Quanto paguei | L2: Valor de Mercado | M2: Ganho | N2: Ganho Anterior | O2: % Ganho | Q2: Min 52 semanas | R2: Max 52 semanas
A3: FUNDOS | B3: FUNDO 24H XP | C3: CDI | E3: 101982.03 | F3: 98433.47 | G3: {=E3-F3} -> 3548.56 | H3: {=(E3-F3)/F3} -> 0.036050339 | I3: 1 | J3: 0.20426506 | K3: 98433.47 | L3: 101982.03 | M3: {=_xlfn.IFERROR(L3-K3,"–")} -> 3548.56 | N3: 0 | O3: {=_xlfn.IFERROR((L3-K3)/K3,"–")} -> 0.036050339 | Q3: 312.51 | R3: 519.1
A4: FUNDOS | B4: BNP PARIBAS | C4: CDI | E4: 159228.9 | F4: 157520.28 | G4: {=E4-F4} -> 1708.62 | H4: {=(E4-F4)/F4} -> 0.010846984 | K4: – | L4: – | M4: {=_xlfn.IFERROR(L4-K4,"–")} -> –
D5: 86532.46 | E5: 72382.58 | F5: {=F4-D5} -> 70987.82 | G5: {=E5-F5} -> 1394.76 | H5: {=(E5-F5)/F5} -> 0.019647878 | I5: 1 | K5: 70987.82 | L5: 72382.58 | M5: {=_xlfn.IFERROR(L5-K5,"–")} -> 1394.76
A6: Portfólio | I6: {=SUM(I3:I5)} -> 2 | K6: {=SUM(K3:K5)} -> 169421.29 | L6: {=SUM(L3:L5)} -> 174364.61 | M6: {=SUM(M3:M5)} -> 4943.32 | N6: {=SUM(N3:N5)} -> 0 | O6: {=(L6-K6)/K6} -> 0.029177679 | P6: {=H3+H4} -> 0.046897324 | Q6: {=SUM(Q3:Q5)} -> 312.51 | R6: {=SUM(R3:R5)} -> 519.1

Sheet FUNDOS - Tabela 1
A1: Tabela 1
A2: 12

Sheet FUNDOS - Tabela 3
A1: Tabela 3

Sheet FUNDOS - Desenhos

Sheet LCI_LCA - Visão Geral
A1: Valor Total de Mercado | B1: {='LCI_LCA - Meu Portfólio'!F3+'LCI_LCA - Meu Portfólio'!F4} -> 2201.93
A2: Ganho/Perda | B2: {='LCI_LCA - Meu Portfólio'!N5-'LCI_LCA - Meu Portfólio'!O5} -> 289.4 | C2: {=IF(B2>0,"↑",IF(B2<0,"↓","–"))} -> ↑
A3: % Alteração | B3: {='LCI_LCA - Meu Portfólio'!Q$5} -> 0.026556961 | C3: {=IF(B3="–","–",IF(B3>0,"↑",IF(B3<0,"↓","–")))} -> ↑

Sheet LCI_LCA - REFERENCIAL
A1: REFERENCIAL
B2: CAIU 10% OU MAIS EM RELAÇÃO AO PREÇO PAGO
B3: CAIU 20% OU MAIS EM RELAÇÃO AO PREÇO PAGO
B4: SUBIU 10% OU MAIS EM RELAÇÃO AO PREÇO PAGO
B5: SUBIU 20% OU MAIS EM RELAÇÃO AO PREÇO PAGO

Sheet LCI_LCA - Meu Portfólio
A2: Símbolo | B2: Nome | C2: Data da Aplicação | D2: Data do vencimento | E2: SETOR | F2: Preço | G2: Preço Pago | H2: Alteração de Preço | I2: % Alteração | J2: QTD Cotas | K2: Preço Pago em Dólares Americanos | L2: Quanto paguei | M2: Valor de Mercado | N2: Ganho | O2: Ganho Anterior | P2: % Ganho | R2: Min 52 semanas | S2: Max 52 semanas
A3: LCI | B3: LCI BRB - MAI26 | C3: 46062 | D3: 46149 | E3: 100% CDI | F3: 1119.55 | G3: 1101.83 | H3: {=F3-G3} -> 17.72 | I3: {=(F3-G3)/G3} -> 0.016082336 | J3: 10 | K3: 0.20426506 | L3: 11018.3 | M3: 11195.5 | N3: {=_xlfn.IFERROR(M3-L3,"–")} -> 177.2 | O3: 0 | P3: {=_xlfn.IFERROR((M3-L3)/L3,"–")} -> 0.016082336 | R3: 312.51 | S3: 519.1
A4: LCA | B4: BANCO RB - JUN/26 | C4: 46080 | D4: 46174 | E4: IPCA + 7,95% ISENTO DE IR | F4: 1082.38 | G4: 1071.16 | H4: {=F4-G4} -> 11.22 | I4: {=(F4-G4)/G4} -> 0.010474626 | J4: 10 | L4: 10711.6 | M4: 10823.8 | N4: {=_xlfn.IFERROR(M4-L4,"–")} -> 112.2
A5: Portfólio | J5: {=SUM(J3:J4)} -> 20 | L5: {=SUM(L3:L4)} -> 21729.9 | M5: {=SUM(M3:M4)} -> 22019.3 | N5: {=SUM(N3:N4)} -> 289.4 | O5: {=SUM(O3:O4)} -> 0 | P5: {=(M5-L5)/L5} -> 0.013318055 | Q5: {=I3+I4} -> 0.026556961 | R5: {=SUM(R3:R4)} -> 312.51 | S5: {=SUM(S3:S4)} -> 519.1

Sheet LCI_LCA - Tabela 1
A1: Tabela 1
A2: 12

Sheet LCI_LCA - Tabela 3
A1: Tabela 3

Sheet LCI_LCA - Desenhos

Sheet Tesouro Direto - TESOURO IPCA +
A1: TESOURO IPCA + 2040
B3: DATA DA APLICAÇÃO | C3: QTD TÍTULOS ADQUIRIDOS | D3: PREÇO DO TÍTULO NA APLICAÇÃO | E3: VALOR INVESTIDO | F3: RENTABILIDADE CONTRATADA | G3: SITUAÇÃO PARA RESGATE ANTECIPADO
G4: RENTABILIDADE BRUTA | I4: VALOR BRUTO $ | J4: TEMPO DE APLICAÇÃO EM DIAS CORRIDOS | K4: ALÍQUOTA I.R | L4: IMPOSTO PREVISTO $ | N4: TAXA DEVIDA (R$) | P4: VALOR LÍQUIDO | Q4: Lucro/Prejuízo
G5: ACUMULADA ANUALIZADA | H5: ACUMULADA | L5: I.R. | M5: IOF | N5: B3 | O5: INSTITUIÇÃO FINANCEIRA
A6: IPCA+ 2040 | B6: 46079 | C6: 28.74 | D6: 1739.68 | E6: {=C6*D6} -> 49998.403 | F6: IPCA + 7,01% | G6: {=IF(J6>0,(1+H6)^(365/J6)-1,"")} -> 0.11155432 | H6: {=IF(E6=0,0,I6/E6-1)} -> 0.020785432 | I6: {=C6*B9} -> 51037.642 | J6: {=DATEDIF(B6,TODAY(),"d")} -> 71 | K6: {=IF(J6<=180,22.5%,IF(J6<=360,20%,IF(J6<=720,17.5%,15%)))} -> 0.225 | L6: {=MAX(0,(I6-E6)*K6)} -> 233.82864 | M6: {=MAX(0,(I6-E6)*B10)} -> 0 | N6: {=I6*B11*(J6/365)} -> 19.85574 | O6: {=J6*B12*(K6/365)} -> 0 | P6: {=I6-L6-M6-N6-O6} -> 50783.957 | Q6: {=P6-E7} -> 785.55402
E7: {=SUM(E6:E6)} -> 49998.403
A9: PU - Hoje | B9: 1775.84
A10: IOF | B10: {=IF(J6>=30,0,CHOOSE(J6,96%,93%,90%,86%,83%,80%,76%,73%,70%,66%,63%,60%,56%,53%,50%,46%,43%,40%,36%,33%,30%,26%,23%,20%,16%,13%,10%,6%,3%))} -> 0
A11: TX - B3 | B11: 0.002
A12: TX - XP | B12: 0

Sheet Tesouro Direto - TESOURO IPCA 1
A1: TESOURO IPCA + 2050
B3: DATA DA APLICAÇÃO | C3: QTD TÍTULOS ADQUIRIDOS | D3: PREÇO DO TÍTULO NA APLICAÇÃO | E3: VALOR INVESTIDO | F3: RENTABILIDADE CONTRATADA | G3: SITUAÇÃO PARA RESGATE ANTECIPADO
G4: RENTABILIDADE BRUTA | I4: VALOR BRUTO $ | J4: TEMPO DE APLICAÇÃO EM DIAS CORRIDOS | K4: ALÍQUOTA I.R | L4: IMPOSTO PREVISTO $ | N4: TAXA DEVIDA (R$) | P4: VALOR LÍQUIDO | Q4: Lucro/Prejuízo
G5: ACUMULADA ANUALIZADA | H5: ACUMULADA | L5: I.R. | M5: IOF | N5: B3 | O5: INSTITUIÇÃO FINANCEIRA
A6: IPCA+ 2050 | B6: 46097 | C6: 22.72 | D6: 885.28 | E6: {=C6*D6} -> 20113.562 | F6: IPCA + 7,06% | G6: {=IF(J6>0,(1+H6)^(365/J6)-1,"")} -> 0.49016538 | H6: {=IF(E6=0,0,I6/E6-1)} -> 0.059630851 | I6: {=C6*B9} -> 21312.95 | J6: {=DATEDIF(B6,TODAY(),"d")} -> 53 | K6: {=IF(J6<=180,22.5%,IF(J6<=360,20%,IF(J6<=720,17.5%,15%)))} -> 0.225 | L6: {=MAX(0,(I6-E6)*K6)} -> 269.86248 | M6: {=MAX(0,(I6-E6)*B10)} -> 0 | N6: {=I6*B11*(J6/365)} -> 6.1895144 | O6: {=J6*B12*(K6/365)} -> 0 | P6: {=I6-L6-M6-N6-O6} -> 21036.898 | Q6: {=P6-E7} -> 923.33681
E7: {=SUM(E6:E6)} -> 20113.562
A9: PU - Hoje | B9: 938.07
A10: IOF | B10: {=IF(J6>=30,0,CHOOSE(J6,96%,93%,90%,86%,83%,80%,76%,73%,70%,66%,63%,60%,56%,53%,50%,46%,43%,40%,36%,33%,30%,26%,23%,20%,16%,13%,10%,6%,3%))} -> 0
A11: TX - B3 | B11: 0.002
A12: TX - XP | B12: 0

Sheet Tesouro Direto - NTN-B Principa
A1: NTN-B Principal - AGO/2060 Tesouro XP
B3: DATA DA APLICAÇÃO | C3: QTD TÍTULOS ADQUIRIDOS | D3: PREÇO DO TÍTULO NA APLICAÇÃO | E3: VALOR INVESTIDO | F3: RENTABILIDADE CONTRATADA | G3: SITUAÇÃO PARA RESGATE ANTECIPADO
G4: RENTABILIDADE BRUTA | I4: VALOR BRUTO $ | J4: TEMPO DE APLICAÇÃO EM DIAS CORRIDOS | K4: ALÍQUOTA I.R | L4: IMPOSTO PREVISTO $ | N4: TAXA DEVIDA (R$) | P4: VALOR LÍQUIDO
G5: ACUMULADA ANUALIZADA | H5: ACUMULADA | L5: I.R. | M5: IOF | N5: B3 | O5: INSTITUIÇÃO FINANCEIRA
A6: NTN-B - 2060 | B6: 46091 | C6: 184 | D6: 544.46 | E6: {=C6*D6} -> 100180.64 | F6: IPCA + 6,45% | G6: {=IF(J6>0,(1+H6)^(365/J6)-1,"")} -> 0.57645189 | H6: {=IF(E6=0,0,I6/E6-1)} -> 0.07635088 | I6: {=C6*B9} -> 107829.52 | J6: {=DATEDIF(B6,TODAY(),"d")} -> 59 | K6: {=IF(J6<=180,22.5%,IF(J6<=360,20%,IF(J6<=720,17.5%,15%)))} -> 0.225 | L6: {=MAX(0,(I6-E6)*K6)} -> 1720.998 | M6: {=MAX(0,(I6-E6)*B10)} -> 0 | N6: {=I6*B11*(J6/365)} -> 34.859954 | O6: {=J6*B12*(K6/365)} -> 0 | P6: {=I6-L6-M6-N6-O6} -> 106073.66
E7: {=SUM(E6:E6)} -> 100180.64
A9: PU - Hoje | B9: 586.03
A10: IOF | B10: {=IF(J6>=30,0,CHOOSE(J6,96%,93%,90%,86%,83%,80%,76%,73%,70%,66%,63%,60%,56%,53%,50%,46%,43%,40%,36%,33%,30%,26%,23%,20%,16%,13%,10%,6%,3%))} -> 0
A11: TX - B3 | B11: 0.002
A12: TX - XP | B12: 0

Sheet Tesouro Direto - NTN-B Princip1
A1: NTN-B Principal - AGO/2050 - Tesouro XP
B3: DATA DA APLICAÇÃO | C3: QTD TÍTULOS ADQUIRIDOS | D3: PREÇO DO TÍTULO NA APLICAÇÃO | E3: VALOR INVESTIDO | F3: RENTABILIDADE CONTRATADA | G3: SITUAÇÃO PARA RESGATE ANTECIPADO
G4: RENTABILIDADE BRUTA | I4: VALOR BRUTO $ | J4: TEMPO DE APLICAÇÃO EM DIAS CORRIDOS | K4: ALÍQUOTA I.R | L4: IMPOSTO PREVISTO $ | N4: TAXA DEVIDA (R$) | P4: VALOR LÍQUIDO
G5: ACUMULADA ANUALIZADA | H5: ACUMULADA | L5: I.R. | M5: IOF | N5: B3 | O5: INSTITUIÇÃO FINANCEIRA
A6: NTN-B - 2050 | B6: 46091 | C6: 54 | D6: 1002.22 | E6: {=C6*D6} -> 54119.88 | F6: IPCA + 6,50% | G6: {=IF(J6>0,(1+H6)^(365/J6)-1,"")} -> 0.55103661 | H6: {=IF(E6=0,0,I6/E6-1)} -> 0.073526771 | I6: {=C6*B9} -> 58099.14 | J6: {=DATEDIF(B6,TODAY(),"d")} -> 59 | K6: {=IF(J6<=180,22.5%,IF(J6<=360,20%,IF(J6<=720,17.5%,15%)))} -> 0.225 | L6: {=MAX(0,(I6-E6)*K6)} -> 895.3335 | M6: {=MAX(0,(I6-E6)*B10)} -> 0 | N6: {=I6*B11*(J6/365)} -> 18.782736 | O6: {=J6*B12*(K6/365)} -> 0 | P6: {=I6-L6-M6-N6-O6} -> 57185.024
E7: {=SUM(E6:E6)} -> 54119.88
A9: PU - Hoje | B9: 1075.91
A10: IOF | B10: {=IF(J6>=30,0,CHOOSE(J6,96%,93%,90%,86%,83%,80%,76%,73%,70%,66%,63%,60%,56%,53%,50%,46%,43%,40%,36%,33%,30%,26%,23%,20%,16%,13%,10%,6%,3%))} -> 0
A11: TX - B3 | B11: 0.002
A12: TX - XP | B12: 0

Sheet Tesouro Direto - IPCA + 2050
A1: IPCA + 2050
B3: DATA DA APLICAÇÃO | C3: QTD TÍTULOS ADQUIRIDOS | D3: PREÇO DO TÍTULO NA APLICAÇÃO | E3: VALOR INVESTIDO | F3: RENTABILIDADE CONTRATADA | G3: SITUAÇÃO PARA RESGATE ANTECIPADO
G4: RENTABILIDADE CONTRATADA | I4: VALOR BRUTO $ | J4: TEMPO DE APLICAÇÃO EM DIAS CORRIDOS | K4: ALÍQUOTA I.R | L4: IMPOSTO PREVISTO $ | N4: TAXA DEVIDA (R$) | P4: VALOR LÍQUIDO
G5: ACUMULADA ANUALIZADA | H5: ACUMULADA | L5: I.R. | M5: IOF | N5: B3 | O5: INSTITUIÇÃO FINANCEIRA
A6: IPCA + 2050 | B6: 46094 | C6: 65.69 | D6: 913.51 | E6: 60008.47 | F6: IPCA + 6,92% | G6: {=IF(J6>0,(1+H6)^(365/J6)-1,"")} -> 0.1887717 | H6: {=IF(E6=0,0,I6/E6-1)} -> 0.026885343 | I6: {=C6*B8} -> 61621.818 | J6: {=DATEDIF(B6,TODAY(),"D")} -> 56 | K6: {=IF(J6<=180,22.5%,IF(J6<=360,20%,IF(J6<=720,17.5%,15%)))} -> 0.225 | L6: {=MAX(0,(I6-E6)*K6)} -> 363.00337 | M6: {=MAX(0,(I6-E6)*B9)} -> 0 | N6: {=I6*B11*(J6/365)} -> 0 | O6: {=J6*C11*(K6/365)} -> 0 | P6: {=I6-L6-M6-N6+O6} -> 61258.815
E7: {=SUM(E6)} -> 60008.47 | O7: TOTAL
A8: PU - Hoje | B8: 938.07
A9: IOF | B9: {=IF(J6>=30,0,CHOOSE(J6,96%,93%,90%,86%,83%,80%,76%,73%,70%,66%,63%,60%,56%,53%,50%,46%,43%,40%,36%,33%,30%,26%,23%,20%,16%,13%,10%,6%,3%))} -> 0
A10: TX - B3 | B10: 0.002
A11: TX - XP | B11: 0

Sheet Tesouro Direto - Meu Portfólio-
A2: Símbolo | B2: Nome | C2: Preço | D2: QTD Ações | E2: Preço Pago em Dólares Americanos | F2: Preço pago em Real | G2: Valor atual da ação em Real | H2: Percentual de lucro | I2: Lucro/Prejuízo | J2: Ganho Anterior | K2: % Ganho
A3: MMM | B3: 3M Company | C3: 143.75 | D3: 0.44444 | E3: 101.14 | F3: 220.06046 | G3: 312.77132 | H3: {=(C3-E3)/E3} -> 0.42129721 | I3: {=_xlfn.IFERROR(G3-F3,"–")} -> 92.710858 | J3: – | K3: {=_xlfn.IFERROR((G3-F3)/F3,"–")} -> 0.42129721
A4: Portfólio | D4: {=SUM(D3:D3)} -> 0.44444 | F4: {=SUM(F3:F3)} -> 220.06046 | G4: {=SUM(G3:G3)} -> 312.77132 | H4: {=SUM(H3:H3)} -> 0.42129721 | I4: {=SUM(I3:I3)} -> 92.710858 | J4: {=SUM(J3:J3)} -> 0 | K4: {=(G4-F4)/F4} -> 0.42129721

Sheet Consolidação - Variação Mensal 
A1: Variação Mensal - 2026
A2: MÊS | B2: VALOR | C2: VARIAÇÃO $ | D2: VARIAÇÃO %
A3: DEZ 2025 | B3: 683590.09 | C3: {=B4-B3} -> 0 | D3: {=(B4-B3)/B3} -> 0
A4: JAN 2026 | B4: 683590.09 | C4: {=B5-B4} -> 0 | D4: {=(B5-B4)/B4} -> 0
A5: FEV 2026 | B5: 683590.09 | C5: {=B6-B5} -> 79275.97 | D5: {=(B6-B5)/B5} -> 0.11597004
A6: MAR 2026 | B6: 762866.06 | C6: {=B7-B6} -> 19636.28 | D6: {=(B7-B6)/B6} -> 0.025740141
A7: ABR 2026 | B7: 782502.34 | C7: {=B8-B7} -> -782502.34 | D7: {=(B8-B7)/B7} -> -1
A8: MAI 2026 | C8: {=B9-B8} -> 0 | D8: {=(B9-B8)/B8}
A9: JUN 2026 | C9: {=B10-B9} -> 0 | D9: {=(B10-B9)/B9}
A10: JUL 2026 | C10: {=B11-B10} -> 0 | D10: {=(B11-B10)/B10}
A11: AGO 2026 | C11: {=B12-B11} -> 0 | D11: {=(B12-B11)/B11}
A12: SET 2026 | C12: {=B13-B12} -> 0 | D12: {=(B13-B12)/B12}
A13: OUT 2026 | C13: {=B14-B13} -> 0 | D13: {=(B14-B13)/B13}
A14: NOV 2026 | C14: {=B15-B14} -> 0 | D14: {=(B15-B14)/B14}
A15: DEZ 2026 | C15: SALDO - 2026 | D15: {=SUM(D3:D14)}

Sheet Consolidação - AÇÕES
A1: AÇÕES
A2: Ações
A3: Papel | B3: Quantidade | C3: % | D3: Valor por ação
A4: {='AÇÕES - Meu Portfólio'!$A3} -> MELI34 | B4: {=SUM('AÇÕES - Meu Portfólio'!H3:H3)} -> 400 | C4: {=D4/D6} -> 0.74071461 | D4: {='AÇÕES - Meu Portfólio'!K3} -> 29396
A5: {='AÇÕES - Meu Portfólio'!$A4} -> BBSE3 | B5: {=SUM('AÇÕES - Meu Portfólio'!H4:H4)} -> 300 | C5: {=D5/D6} -> 0.25928539 | D5: {='AÇÕES - Meu Portfólio'!K4} -> 10290
B6: TOTAL | D6: {=SUM(D4:D5)} -> 39686

Sheet Consolidação - Projeção Anual 2
A1: Projeção Anual 2026
A2: Ativos | B2: Total de rendimentos | C2: PERCENTUAL DA CARTEIRA | D2: Meta DEZ2026
A3: AÇÕES - BR | B3: {='Consolidação - AÇÕES'!D6} -> 39686 | C3: {=B3/B14} -> 0.050716781 | D3: 38000
A4: ETF - BRASIL | B4: {='Consolidação - ETF - BRASIL'!C4} -> 31226 | C4: {=B4/B14} -> 0.039905312 | D4: 38000
A5: ETF - USA | B5: {='Consolidação - ETF - USA'!D10} -> 24349.406 | C5: {=B5/B14} -> 0.031117358 | D5: 28000
A6: FUNDOS IMOBILIÁRIOS | B6: {='Consolidação - FUNDOS IMOBILIÁR'!D6} -> 29988.78 | C6: {=B6/B14} -> 0.038324205 | D6: 43000
A7: REIT’S | B7: {='Consolidação - REIT’S'!D6} -> 7902.2825 | C7: {=B7/B14} -> 0.010098733 | D7: 33000
A8: STOCKS | B8: {='Consolidação - STOCKS'!D4} -> 3287.6177 | C8: {=B8/B14} -> 0.0042014157
A9: CDB | B9: {='Consolidação - CDB'!D5} -> 2157.0644 | C9: {=B9/B14} -> 0.0027566236
A10: CRI/CRA | B10: {='Consolidação - CRI_CRA'!D7} -> 212441.74 | C10: {=B10/B14} -> 0.27149023
A11: FUNDOS | B11: {='Consolidação - FUNDOS'!D5} -> 174364.61 | C11: {=B11/B14} -> 0.22282951
A12: LCI/LCA | B12: {='Consolidação - LCI_LCA'!D5} -> 22019.3 | C12: {=B12/B14} -> 0.028139596
A13: TESOURO DIRETO | B13: {='Consolidação - TESOURO DIRETO'!D7} -> 235079.54 | C13: {=B13/B14} -> 0.30042024
A14: TOTAL | B14: {=B3+B4+B5+B6+B7+B8+B9+B10+B11+B12+B13} -> 782502.34 | C14: {=SUM(C3:C13)} -> 1 | D14: {=D3+D4+D5+D6+D7} -> 180000

Sheet Consolidação - ETF - BRASIL
A1: ETF - BRASIL
A2: ETF | B2: QUANTIDADE | C2: VALOR DO FUNDO
A3: {='ETF BRASIL - Meu Portfólio'!$A3} -> COIN11 | B3: {=SUM('ETF BRASIL - Meu Portfólio'!H3)} -> 650 | C3: {='ETF BRASIL - Meu Portfólio'!K3} -> 31226
B4: TOTAL | C4: {=C3} -> 31226

Sheet Consolidação - ETF - USA
A1: ETF - USA
A2: ETF | B2: QUANTIDADE | C2: % | D2: VALOR DO ETF
A3: {='ETF USA - Meu Portfólio'!$A3} -> TLT | B3: {=SUM('ETF USA - Meu Portfólio'!H3)} -> 5.677 | C3: {=D3/D10} -> 0.097760591 | D3: {=SUM('ETF USA - Meu Portfólio'!K3)} -> 2380.4123
A4: {='ETF USA - Meu Portfólio'!$A4} -> BND | B4: {='ETF USA - Meu Portfólio'!H4} -> 6.733 | C4: {=D4/D10} -> 0.099308288 | D4: {='ETF USA - Meu Portfólio'!K4} -> 2418.0978
A5: {='ETF USA - Meu Portfólio'!$A5} -> IUSB | B5: {=SUM('ETF USA - Meu Portfólio'!H5)} -> 21.307 | C5: {=D5/D10} -> 0.19757371 | D5: {='ETF USA - Meu Portfólio'!K5} -> 4810.8025
A6: {='ETF USA - Meu Portfólio'!$A6} -> JCPB | B6: {='ETF USA - Meu Portfólio'!H6} -> 10.493 | C6: {=D6/D10} -> 0.098923042 | D6: {='ETF USA - Meu Portfólio'!K6} -> 2408.7173
A7: {='ETF USA - Meu Portfólio'!$A7} -> IAGG | B7: {='ETF USA - Meu Portfólio'!H7} -> 5.981 | C7: {=D7/D10} -> 0.06017397 | D7: {='ETF USA - Meu Portfólio'!K7} -> 1465.2004
A8: {='ETF USA - Meu Portfólio'!$A8} -> IBIT | B8: {='ETF USA - Meu Portfólio'!H8} -> 26.911 | C8: {=D8/D10} -> 0.24564235 | D8: {='ETF USA - Meu Portfólio'!K8} -> 5981.2453
A9: {='ETF USA - Meu Portfólio'!$A9} -> TFLO | B9: {=SUM('ETF USA - Meu Portfólio'!H9)} -> 19.751 | C9: {=D9/D10} -> 0.20061804 | D9: {='ETF USA - Meu Portfólio'!K9} -> 4884.9301
B10: TOTAL | C10: {=SUM(C3:C9)} -> 1 | D10: {=SUM(D3:D9)} -> 24349.406

Sheet Consolidação - FUNDOS IMOBILIÁR
A1: FUNDOS IMOBILIÁRIOS
A2: FUNDOS | B2: QUANTIDADE | C2: % | D2: VALOR DO FUNDO
A3: {='Fundos Imobiliários - Meu Portf'!$A3} -> MCCI11 | B3: {=SUM('Fundos Imobiliários - Meu Portf'!H3)} -> 169 | C3: {=D3/D6} -> 0.54235484 | D3: {='Fundos Imobiliários - Meu Portf'!K3} -> 16264.56
A4: {='Fundos Imobiliários - Meu Portf'!$A4} -> PCIP11 | B4: {=SUM('Fundos Imobiliários - Meu Portf'!H4)} -> 150 | C4: {=D4/D6} -> 0.43086114 | D4: {='Fundos Imobiliários - Meu Portf'!K4} -> 12921
A5: {='Fundos Imobiliários - Meu Portf'!$A5} -> CXCI11 | B5: {=SUM('Fundos Imobiliários - Meu Portf'!H5)} -> 11 | C5: {=D5/D6} -> 0.026784017 | D5: {='Fundos Imobiliários - Meu Portf'!K5} -> 803.22
B6: TOTAL | C6: {=SUM(C3:C5)} -> 1 | D6: {=D3+D5+D4} -> 29988.78

Sheet Consolidação - REIT’S
A1: REIT’S
A2: FUNDOS | B2: QUANTIDADE | C2: % | D2: VALOR DO FUNDO
A3: {='Reit''s - Meu Portfólio'!$A3} -> PSA | B3: {=SUM('Reit''s - Meu Portfólio'!H3)} -> 1.907 | C3: {=D3/D6} -> 0.36544844 | D3: {='Reit''s - Meu Portfólio'!K3} -> 2887.8768
A4: {='Reit''s - Meu Portfólio'!$A4} -> VICI | B4: {=SUM('Reit''s - Meu Portfólio'!H4)} -> 17.825 | C4: {=D4/D6} -> 0.31792492 | D4: {='Reit''s - Meu Portfólio'!K4} -> 2512.3326
A5: {='Reit''s - Meu Portfólio'!$A5} -> AMT | B5: {=SUM('Fundos Imobiliários - Meu Portf'!H5)} -> 11 | C5: {=D5/D6} -> 0.31662664 | D5: {='Reit''s - Meu Portfólio'!K5} -> 2502.0732
B6: TOTAL | C6: {=SUM(C3:C5)} -> 1 | D6: {=D3+D5+D4} -> 7902.2825

Sheet Consolidação - STOCKS
A1: STOCKS
A2: FUNDOS | B2: QUANTIDADE | C2: % | D2: VALOR DO FUNDO
A3: {='STOCKS - Meu Portfólio'!$A3} -> RACE | B3: {=SUM('STOCKS - Meu Portfólio'!H3)} -> 1.99 | C3: {=D3/D4} -> 1 | D3: {='STOCKS - Meu Portfólio'!K3} -> 3287.6177
B4: TOTAL | C4: {=C3} -> 1 | D4: {=D3} -> 3287.6177

Sheet Consolidação - CDB
A1: CDB
A2: FUNDOS | B2: QUANTIDADE | C2: % | D2: VALOR DO FUNDO
A3: {='CDB - Meu Portfólio'!B3} -> CDB XP - JAN/28 | B3: {=SUM('CDB - Meu Portfólio'!I3)} -> 1000 | C3: {=D3/D5} -> 0.48461706 | D3: {='CDB - Meu Portfólio'!R6} -> 1045.3502
A4: {='CDB - Meu Portfólio-1'!B3} -> CDB XP - AGO/26 | B4: {='CDB - Meu Portfólio-1'!O3} -> 1 | C4: {=D4/D5} -> 0.51538294 | D4: {='CDB - Meu Portfólio-1'!K6} -> 1111.7142
B5: TOTAL | C5: {=SUM(C3:C4)} -> 1 | D5: {=D3+D4} -> 2157.0644

Sheet Consolidação - CRI_CRA
A1: CRI/CRA
A2: FUNDOS | B2: QUANTIDADE | C2: % | D2: VALOR DO FUNDO
A3: {='CRI_CRA - Meu Portfólio'!B3} -> AÇO VERDE - JUN/29 | B3: {=SUM('CRI_CRA - Meu Portfólio'!O3)} -> 39 | C3: {=D3/D7} -> 0.20951589 | D3: {='CRI_CRA - Meu Portfólio'!R3} -> 44509.92
A4: {='CRI_CRA - Meu Portfólio-1'!B4} -> BTG PACTUAL - NOV/33 | B4: {='CRI_CRA - Meu Portfólio-1'!J4} -> 1 | C4: {=D4/D7} -> 0.40719917 | D4: {='CRI_CRA - Meu Portfólio-1'!M4} -> 86506.1
A5: {='CRI_CRA - Meu Portfólio-1'!B5} -> MATEUS SUP JUL/34 | B5: {='CRI_CRA - Meu Portfólio-1'!J5} -> 42 | C5: {=D5/D7} -> 0.17296093 | D5: {='CRI_CRA - Meu Portfólio-1'!M5} -> 36744.12
A6: {='CRI_CRA - Meu Portfólio-1'!B6} -> SÃO CARLOS SET/29 | B6: {='CRI_CRA - Meu Portfólio-1'!J6} -> 40 | C6: {=D6/D7} -> 0.21032402 | D6: {='CRI_CRA - Meu Portfólio-1'!M6} -> 44681.6
B7: TOTAL | C7: {=SUM(C3:C6)} -> 1 | D7: {=D3+D4+D5+D6} -> 212441.74

Sheet Consolidação - FUNDOS
A1: FUNDOS
A2: FUNDOS | B2: QUANTIDADE | C2: % | D2: VALOR DO FUNDO
A3: {='FUNDOS - Meu Portfólio'!B3} -> FUNDO 24H XP | B3: {=SUM('FUNDOS - Meu Portfólio'!I3)} -> 1 | C3: {=D3/D5} -> 0.58487803 | D3: {='FUNDOS - Meu Portfólio'!L3} -> 101982.03
A4: {='FUNDOS - Meu Portfólio'!B4} -> BNP PARIBAS | B4: {=SUM('FUNDOS - Meu Portfólio'!I4)} -> 0 | C4: {=D4/D5} -> 0.41512197 | D4: {='FUNDOS - Meu Portfólio'!L5} -> 72382.58
B5: TOTAL | C5: {=SUM(C3:C4)} -> 1 | D5: {=D3+D4} -> 174364.61

Sheet Consolidação - LCI_LCA
A1: LCI/LCA
A2: FUNDOS | B2: QUANTIDADE | C2: % | D2: VALOR DO FUNDO
A3: {='LCI_LCA - Meu Portfólio'!B3} -> LCI BRB - MAI26 | B3: {=SUM('LCI_LCA - Meu Portfólio'!J3)} -> 10 | C3: {=D3/D5} -> 0.50844032 | D3: {='LCI_LCA - Meu Portfólio'!M3} -> 11195.5
A4: {='LCI_LCA - Meu Portfólio'!B4} -> BANCO RB - JUN/26 | B4: {=SUM('LCI_LCA - Meu Portfólio'!J4)} -> 10 | C4: {=D4/D5} -> 0.49155968 | D4: {='LCI_LCA - Meu Portfólio'!M4} -> 10823.8
B5: TOTAL | C5: {=SUM(C3:C4)} -> 1 | D5: {=D3+D4} -> 22019.3

Sheet Consolidação - TESOURO DIRETO
A1: TESOURO DIRETO
A2: FUNDOS | B2: QUANTIDADE | C2: % | D2: VALOR DO FUNDO
A3: {='Tesouro Direto - TESOURO IPCA +'!A6} -> IPCA+ 2040 | B3: {=SUM('Tesouro Direto - TESOURO IPCA +'!C6)} -> 28.74 | C3: {=D3/D7} -> 0.21602883 | D3: {='Tesouro Direto - TESOURO IPCA +'!P6} -> 50783.957
A4: {='Tesouro Direto - TESOURO IPCA 1'!A6} -> IPCA+ 2050 | B4: {=SUM('Tesouro Direto - TESOURO IPCA 1'!C6)} -> 22.72 | C4: {=D4/D7} -> 0.089488427 | D4: {='Tesouro Direto - TESOURO IPCA 1'!P6} -> 21036.898
A5: {='Tesouro Direto - NTN-B Principa'!A6} -> NTN-B - 2060 | B5: {=SUM('Tesouro Direto - NTN-B Principa'!C6)} -> 184 | C5: {=D5/D7} -> 0.45122456 | D5: {='Tesouro Direto - NTN-B Principa'!P6} -> 106073.66
A6: {='Tesouro Direto - NTN-B Princip1'!A6} -> NTN-B - 2050 | B6: {=SUM('Tesouro Direto - NTN-B Princip1'!C6)} -> 54 | C6: {=D6/D7} -> 0.24325819 | D6: {='Tesouro Direto - NTN-B Princip1'!P6} -> 57185.024
B7: TOTAL | C7: {=SUM(C3:C6)} -> 1 | D7: {=D3+D4+D5+D6} -> 235079.54

Sheet Consolidação - Desenhos
